## 2.6. Error Handling in Alvamind ðŸš§

Alvamind promotes a robust approach to error handling, inspired by Railway-Oriented Programming (ROP). This section explains ROP, how to use Alvamind's features for error handling, and best practices.

### 2.6.1. Railway-Oriented Programming: The Two-Track Approach

Railway-Oriented Programming visualizes the flow of execution as a railway track with two tracks:

*   **Success Track (ðŸŸ¢):** The normal flow when everything goes as expected.
*   **Failure Track (ðŸ”´):** The flow when an error occurs.

The core idea is to chain functions that automatically switch to the failure track if an error occurs. This avoids nested `try-catch` blocks and makes error handling more explicit.

**Key Concepts:**

*   **`Either`:** Alvamind encourages the use of the `Either` type (from `fp-ts`, available through the module context) to represent computations that can succeed or fail. `Either` has two constructors:
    *   `E.right(value)`: Represents a successful result (`value`).
    *   `E.left(error)`: Represents a failed result (`error`).

*   **Chaining with `E.chain`:** The `E.chain` function (from `fp-ts`, via context) chains operations that return `Either` values. If *any* operation returns `E.left`, subsequent operations are skipped, and the `E.left` (error) is propagated.

*   **Handling Both Tracks:** The `E.fold` function (from `fp-ts`, via context) lets you handle both success and failure cases at the end.

**Example:**

```typescript
import { Alvamind } from 'alvamind';

const userModule = new Alvamind({ name: 'UserModule' })
.derive(({ E, TE, pipe }) => ({ // Access fp-ts functions through context
  validateUser: (input: unknown): E.Either<Error, { name: string }> => {
    if (typeof input === 'object' && input !== null && 'name' in input && typeof input.name === 'string') {
      return E.right({ name: input.name });
    }
    return E.left(new Error('Invalid user data'));
  },
  normalizeName: (user: { name: string }): { name: string } => ({
    ...user,
    name: user.name.trim().toLowerCase(),
  }),
  saveUser: (user: { name: string }) =>
    Promise.resolve({ id: '123', ...user }),

  processUser: (input: unknown) =>
    pipe(
      validateUser(input),      // 1. Validate (returns Either)
      E.map(normalizeName),    // 2. Normalize (only on success)
      TE.fromEither,           // 3. Convert to TaskEither for async
      TE.chain(saveUser)         // 4. Save (only on success)
    ),
}));

const successResult = await userModule.processUser({ name: '  Alice ' }); // Success
const failureResult = await userModule.processUser({ name: 123 });      // Failure

// Handle the result (using E.fold, also from the Alvamind context):

pipe(
    successResult,
    E.fold(
        (error) => console.log('Error', error),
        (success) => console.log('Success', success)
    )
)
```

**Benefits of ROP:**

*   **Explicit Error Handling:** Errors are handled explicitly.
*   **No Nested `try-catch`:** Avoids the "pyramid of doom."
*   **Improved Readability:** The flow is easier to follow.
*   **Composability:** Error handling logic can be composed.

### 2.6.2. `.catch()` for Error Handling: Specific Error Types

The `.catch()` method lets you register handlers for specific error types.  This allows you to handle different errors in different ways.

```typescript
import { Alvamind } from 'alvamind';

class ValidationError extends Error {
  constructor(message: string) {
    super(message);
    this.name = 'ValidationError';
  }
}

class DatabaseError extends Error {
    constructor(message: string) {
        super(message);
        this.name = 'DatabaseError';
    }
}

const userModule = new Alvamind({ name: 'UserModule' })
  .derive(() => ({
    validate: (input: {name: string}): {name: string} => {
        if(!input.name) {
            throw new ValidationError('Name is required'); // Throw specific error
        }
        return input;
    },
    saveToDatabase: async (data:{name: string}) => {
      // Simulate a database error
      throw new DatabaseError('Failed to connect to database');
    }
  }))
  .pipe(
    'createUser',
    ({validate, saveToDatabase}) => async (input: {name: string}) => {
        try {
            const validated = validate(input);
            return await saveToDatabase(validated);
        } catch(error) {
            //catch all error
            throw error;
        }
    }
  )
  .catch(ValidationError, (error, context) => { // Handle ValidationError
    console.error('Validation Error:', error.message);
    // Optionally, update state:
    context.state.set({ error: 'Validation failed' });
  })
  .catch(DatabaseError, (error) => { // Handle DatabaseError
    console.error('Database Error:', error.message);
  });

async function run() {
    await userModule.createUser({name: ''}); // Triggers ValidationError
    await userModule.createUser({name: 'Test'}); // Triggers DatabaseError
}
run();
```

**Explanation:**

1.  **Custom Error Types:** Define `ValidationError` and `DatabaseError`.
2.  **Throwing Errors:**  `validate` throws a `ValidationError`. `saveToDatabase` throws a `DatabaseError`.
3.  **`.catch(ErrorType, handler)`:**
    *   The first argument is the *error type* (e.g., `ValidationError`).
    *   The second argument is a *handler function* that receives the error and the Alvamind context.
4.  **Try Catch:** Because we want to handle a specific error type, so the pipeline is wrapped with a `try-catch` block.

**Key Features of `.catch()`:**

*   **Type-Specific Handling:** Handle different errors differently.
*   **Context Access:** The handler has access to the context (update state, etc.).
*   **Multiple Handlers:** You can register multiple `.catch()` handlers.
*   **Error Propagation:**  If an error is *not* caught, it will be thrown.

### 2.6.3. `.retry()` for Retrying Operations: Handling Transient Errors

The `.retry()` method automatically retries a function if it fails.  This is useful for transient errors like network timeouts.

```typescript
import { Alvamind } from 'alvamind';

const networkModule = new Alvamind({ name: 'NetworkModule' })
  .derive(() => ({
    fetchData: async (url: string) => {
      // Simulate a flaky network request
      if (Math.random() < 0.5) {
        throw new Error('Network request failed');
      }
      return { data: 'Some data' };
    },
  }))
  .retry({
    attempts: 3, // Retry up to 3 times
    delay: 1000,  // Wait 1 second between retries
    backoff: 'linear', // Use linear backoff. options: 'fixed' | 'linear' | 'exponential'
    when: (error) => error.message === 'Network request failed', // Only retry specific errors
  })
  .pipe(
    'getData',
        ({ fetchData }) => async (url: string) => {
          // The `fetchData` function will be automatically retried if it fails
          return networkModule.execute(() => fetchData(url));
        }
  );

async function run() {
    const data = await networkModule.getData('https://example.com');
    console.log(data);
}
run();
```

**Explanation:**

1.  **`fetchData`:** Simulates a network request that might fail.
2.  **`.retry({ ... })`:**
    *   `attempts`: Maximum retry attempts.
    *   `delay`: Initial delay between retries (milliseconds).
    *   `backoff`:  If `true`, use exponential backoff (delay increases).
    *   `when`: Optional function; if it returns `true`, retry the operation.
3.  **`networkModule.execute`:** Execute from `.retry()` to handle automatic retry.

**Key Features of `.retry()`:**

*   **Automatic Retries:** Handles transient errors without manual intervention.
*   **Configurable:** Control attempts, delay, backoff, and retry conditions.
*   **Error Filtering:** Specify which errors trigger a retry.
*   **Type safety**: Type is automatically inferred.

### 2.6.4. `.fallback()` for Default Values: Providing Alternatives

The `.fallback()` method provides a fallback value if an operation fails.  This can prevent errors from propagating.

```typescript
import { Alvamind } from 'alvamind';

const userModule = new Alvamind({ name: 'UserModule' })
.derive(({E, pipe})=>({
    fetchUser: (id: string) => {
        if(id === '123') {
            return E.right({id, name: 'Alice'})
        }
        return E.left(new Error('User Not Found'));
    }
}))
.pipe(
    'getUser',
        ({fetchUser, E}) => (id: string) =>
        pipe(
          fetchUser(id), // Might return E.left(Error)
          E.getOrElse(() => ({ id: 'default', name: 'Guest' })) // Fallback value
        )
)
.fallback((error) => {
    console.error('An error Occured', error);
    return {id: 'fallback', name: 'Unknown'};
});

const user1 = await userModule.getUser('123');     // Returns Alice
const user2 = await userModule.getUser('invalid'); // Returns Guest
```

**Explanation:**
- Using `E.getOrElse` from `fp-ts` to get the value from `Either`.
- Using `.fallback` method if error is occurred.

**Key Features of `.fallback()`:**

*   **Error Prevention:** Prevents errors from crashing your application.
*   **Default Values:** Provides sensible defaults.
*   **Simplified Logic:** Avoids complex conditional logic.

### 2.6.5. Custom Error Types: Improved Error Handling

Using custom error types (like in the `.catch()` example) is highly recommended. This lets you:

*   **Differentiate Errors:** Distinguish between validation, network, database errors, etc.
*   **Attach Metadata:** Add information to your errors (e.g., error codes).
*   **Handle Errors Specifically:** Use `.catch()` to handle different error types differently.

By combining ROP, `.catch()`, `.retry()`, `.fallback()`, and custom error types, Alvamind provides a comprehensive error handling system. These tools let you handle errors gracefully, recover from failures, and build resilient applications. The revised section emphasizes ROP and the use of `fp-ts` functions *through* the Alvamind context, consistent with the overall goal of presenting Alvamind as the primary interface.  Examples are streamlined for clarity.
